06/16/2022 02:59:01 PM: 'latin-1' codec can't encode characters in position 70-79: ordinal not in range(256)
Traceback (most recent call last):
  File "D:\Python Projects\Telegram Bot\main.py", line 903, in parameter_confirmation
    msg = parsers.get_data(tablegroups_path, user)
  File "D:\Python Projects\Telegram Bot\parsers.py", line 490, in get_data
    write_pdf(data, header)
  File "D:\Python Projects\Telegram Bot\parsers.py", line 530, in write_pdf
    pdf.output("Результати пошуку.pdf", "F")
  File "D:\Python Projects\Telegram Bot\env\lib\site-packages\fpdf\fpdf.py", line 1065, in output
    self.close()
  File "D:\Python Projects\Telegram Bot\env\lib\site-packages\fpdf\fpdf.py", line 246, in close
    self._enddoc()
  File "D:\Python Projects\Telegram Bot\env\lib\site-packages\fpdf\fpdf.py", line 1636, in _enddoc
    self._putpages()
  File "D:\Python Projects\Telegram Bot\env\lib\site-packages\fpdf\fpdf.py", line 1170, in _putpages
    p = self.pages[n].encode("latin1") if PY3K else self.pages[n]
UnicodeEncodeError: 'latin-1' codec can't encode characters in position 70-79: ordinal not in range(256)
06/16/2022 03:00:35 PM: 'latin-1' codec can't encode characters in position 70-79: ordinal not in range(256)
Traceback (most recent call last):
  File "D:\Python Projects\Telegram Bot\main.py", line 903, in parameter_confirmation
    msg = parsers.get_data(tablegroups_path, user)
  File "D:\Python Projects\Telegram Bot\parsers.py", line 490, in get_data
    write_pdf(data, header)
  File "D:\Python Projects\Telegram Bot\parsers.py", line 530, in write_pdf
    pdf.output("Результати пошуку.pdf", "F")
  File "D:\Python Projects\Telegram Bot\env\lib\site-packages\fpdf\fpdf.py", line 1065, in output
    self.close()
  File "D:\Python Projects\Telegram Bot\env\lib\site-packages\fpdf\fpdf.py", line 246, in close
    self._enddoc()
  File "D:\Python Projects\Telegram Bot\env\lib\site-packages\fpdf\fpdf.py", line 1636, in _enddoc
    self._putpages()
  File "D:\Python Projects\Telegram Bot\env\lib\site-packages\fpdf\fpdf.py", line 1170, in _putpages
    p = self.pages[n].encode("latin1") if PY3K else self.pages[n]
UnicodeEncodeError: 'latin-1' codec can't encode characters in position 70-79: ordinal not in range(256)
06/16/2022 03:16:39 PM: 'charmap' codec can't encode characters in position 0-2: character maps to <undefined>
Traceback (most recent call last):
  File "D:\Python Projects\Telegram Bot\main.py", line 903, in parameter_confirmation
    msg = parsers.get_data(tablegroups_path, user)
  File "D:\Python Projects\Telegram Bot\parsers.py", line 490, in get_data
    write_pdf(data, header)
  File "D:\Python Projects\Telegram Bot\parsers.py", line 520, in write_pdf
    pdf_key = key.encode('cp1252').decode('cp1252')
  File "C:\Users\olexa\AppData\Local\Programs\Python\Python310\lib\encodings\cp1252.py", line 12, in encode
    return codecs.charmap_encode(input,errors,encoding_table)
UnicodeEncodeError: 'charmap' codec can't encode characters in position 0-2: character maps to <undefined>
06/16/2022 04:13:39 PM: FPDF error: Undefined font: dejavusans B
Traceback (most recent call last):
  File "D:\Python Projects\Telegram Bot\main.py", line 903, in parameter_confirmation
    msg = parsers.get_data(tablegroups_path, user)
  File "D:\Python Projects\Telegram Bot\parsers.py", line 490, in get_data
    write_pdf(data, header)
  File "D:\Python Projects\Telegram Bot\parsers.py", line 510, in write_pdf
    pdf.add_page()
  File "D:\Python Projects\Telegram Bot\env\lib\site-packages\fpdf\fpdf.py", line 290, in add_page
    self.header()
  File "D:\Python Projects\Telegram Bot\parsers.py", line 45, in header
    self.set_font('DejaVuSans', 'B', 20)
  File "D:\Python Projects\Telegram Bot\env\lib\site-packages\fpdf\fpdf.py", line 603, in set_font
    self.error('Undefined font: '+family+' '+style)
  File "D:\Python Projects\Telegram Bot\env\lib\site-packages\fpdf\fpdf.py", line 227, in error
    raise RuntimeError('FPDF error: '+msg)
RuntimeError: FPDF error: Undefined font: dejavusans B
06/16/2022 04:18:19 PM: FPDF error: Undefined font: dejavusans B
Traceback (most recent call last):
  File "D:\Python Projects\Telegram Bot\main.py", line 903, in parameter_confirmation
    msg = parsers.get_data(tablegroups_path, user)
  File "D:\Python Projects\Telegram Bot\parsers.py", line 490, in get_data
    write_pdf(data, header)
  File "D:\Python Projects\Telegram Bot\parsers.py", line 511, in write_pdf
    pdf.add_page()
  File "D:\Python Projects\Telegram Bot\env\lib\site-packages\fpdf\fpdf.py", line 290, in add_page
    self.header()
  File "D:\Python Projects\Telegram Bot\parsers.py", line 45, in header
    self.set_font('DejaVuSans', 'B', 20)
  File "D:\Python Projects\Telegram Bot\env\lib\site-packages\fpdf\fpdf.py", line 603, in set_font
    self.error('Undefined font: '+family+' '+style)
  File "D:\Python Projects\Telegram Bot\env\lib\site-packages\fpdf\fpdf.py", line 227, in error
    raise RuntimeError('FPDF error: '+msg)
RuntimeError: FPDF error: Undefined font: dejavusans B
06/16/2022 04:23:28 PM: TTF Font file not found: DejaVuSansCondensed.ttf
Traceback (most recent call last):
  File "D:\Python Projects\Telegram Bot\main.py", line 903, in parameter_confirmation
    msg = parsers.get_data(tablegroups_path, user)
  File "D:\Python Projects\Telegram Bot\parsers.py", line 490, in get_data
    write_pdf(data, header)
  File "D:\Python Projects\Telegram Bot\parsers.py", line 508, in write_pdf
    pdf.add_font('DejaVu', '', 'DejaVuSansCondensed.ttf', uni=True)
  File "D:\Python Projects\Telegram Bot\env\lib\site-packages\fpdf\fpdf.py", line 469, in add_font
    raise RuntimeError("TTF Font file not found: %s" % fname)
RuntimeError: TTF Font file not found: DejaVuSansCondensed.ttf
06/16/2022 04:25:46 PM: FPDF error: Undefined font: dejavusans B
Traceback (most recent call last):
  File "D:\Python Projects\Telegram Bot\main.py", line 903, in parameter_confirmation
    msg = parsers.get_data(tablegroups_path, user)
  File "D:\Python Projects\Telegram Bot\parsers.py", line 490, in get_data
    write_pdf(data, header)
  File "D:\Python Projects\Telegram Bot\parsers.py", line 510, in write_pdf
    pdf.add_page()
  File "D:\Python Projects\Telegram Bot\env\lib\site-packages\fpdf\fpdf.py", line 290, in add_page
    self.header()
  File "D:\Python Projects\Telegram Bot\parsers.py", line 45, in header
    self.set_font('DejaVuSans', 'B', 20)
  File "D:\Python Projects\Telegram Bot\env\lib\site-packages\fpdf\fpdf.py", line 603, in set_font
    self.error('Undefined font: '+family+' '+style)
  File "D:\Python Projects\Telegram Bot\env\lib\site-packages\fpdf\fpdf.py", line 227, in error
    raise RuntimeError('FPDF error: '+msg)
RuntimeError: FPDF error: Undefined font: dejavusans B
06/16/2022 04:33:14 PM: FPDF error: Undefined font: dejavusans B
Traceback (most recent call last):
  File "D:\Python Projects\Telegram Bot\main.py", line 903, in parameter_confirmation
    msg = parsers.get_data(tablegroups_path, user)
  File "D:\Python Projects\Telegram Bot\parsers.py", line 490, in get_data
    write_pdf(data, header)
  File "D:\Python Projects\Telegram Bot\parsers.py", line 512, in write_pdf
    pdf.add_page()
  File "D:\Python Projects\Telegram Bot\env\lib\site-packages\fpdf\fpdf.py", line 290, in add_page
    self.header()
  File "D:\Python Projects\Telegram Bot\parsers.py", line 45, in header
    self.set_font('DejaVuSans', 'B', 20)
  File "D:\Python Projects\Telegram Bot\env\lib\site-packages\fpdf\fpdf.py", line 603, in set_font
    self.error('Undefined font: '+family+' '+style)
  File "D:\Python Projects\Telegram Bot\env\lib\site-packages\fpdf\fpdf.py", line 227, in error
    raise RuntimeError('FPDF error: '+msg)
RuntimeError: FPDF error: Undefined font: dejavusans B
06/16/2022 04:36:20 PM: FPDF error: Undefined font: dejavu 
Traceback (most recent call last):
  File "D:\Python Projects\Telegram Bot\main.py", line 903, in parameter_confirmation
    msg = parsers.get_data(tablegroups_path, user)
  File "D:\Python Projects\Telegram Bot\parsers.py", line 480, in get_data
    write_pdf(data, header)
  File "D:\Python Projects\Telegram Bot\parsers.py", line 500, in write_pdf
    pdf.set_font("DejaVu", size=12)
  File "D:\Python Projects\Telegram Bot\env\lib\site-packages\fpdf\fpdf.py", line 603, in set_font
    self.error('Undefined font: '+family+' '+style)
  File "D:\Python Projects\Telegram Bot\env\lib\site-packages\fpdf\fpdf.py", line 227, in error
    raise RuntimeError('FPDF error: '+msg)
RuntimeError: FPDF error: Undefined font: dejavu 
06/16/2022 04:51:58 PM: Error while getting Updates: urllib3 HTTPError ('Connection aborted.', RemoteDisconnected('Remote end closed connection without response'))
06/16/2022 04:51:58 PM: No error handlers are registered, logging exception.
Traceback (most recent call last):
  File "D:\Python Projects\Telegram Bot\env\lib\site-packages\telegram\vendor\ptb_urllib3\urllib3\connectionpool.py", line 614, in urlopen
    httplib_response = self._make_request(conn, method, url,
  File "D:\Python Projects\Telegram Bot\env\lib\site-packages\telegram\vendor\ptb_urllib3\urllib3\connectionpool.py", line 402, in _make_request
    six.raise_from(e, None)
  File "<string>", line 2, in raise_from
  File "D:\Python Projects\Telegram Bot\env\lib\site-packages\telegram\vendor\ptb_urllib3\urllib3\connectionpool.py", line 398, in _make_request
    httplib_response = conn.getresponse()
  File "C:\Users\olexa\AppData\Local\Programs\Python\Python310\lib\http\client.py", line 1374, in getresponse
    response.begin()
  File "C:\Users\olexa\AppData\Local\Programs\Python\Python310\lib\http\client.py", line 318, in begin
    version, status, reason = self._read_status()
  File "C:\Users\olexa\AppData\Local\Programs\Python\Python310\lib\http\client.py", line 287, in _read_status
    raise RemoteDisconnected("Remote end closed connection without"
http.client.RemoteDisconnected: Remote end closed connection without response

During handling of the above exception, another exception occurred:

Traceback (most recent call last):
  File "D:\Python Projects\Telegram Bot\env\lib\site-packages\telegram\utils\request.py", line 259, in _request_wrapper
    resp = self._con_pool.request(*args, **kwargs)
  File "D:\Python Projects\Telegram Bot\env\lib\site-packages\telegram\vendor\ptb_urllib3\urllib3\request.py", line 68, in request
    return self.request_encode_body(method, url, fields=fields,
  File "D:\Python Projects\Telegram Bot\env\lib\site-packages\telegram\vendor\ptb_urllib3\urllib3\request.py", line 148, in request_encode_body
    return self.urlopen(method, url, **extra_kw)
  File "D:\Python Projects\Telegram Bot\env\lib\site-packages\telegram\vendor\ptb_urllib3\urllib3\poolmanager.py", line 244, in urlopen
    response = conn.urlopen(method, u.request_uri, **kw)
  File "D:\Python Projects\Telegram Bot\env\lib\site-packages\telegram\vendor\ptb_urllib3\urllib3\connectionpool.py", line 665, in urlopen
    retries = retries.increment(method, url, error=e, _pool=self,
  File "D:\Python Projects\Telegram Bot\env\lib\site-packages\telegram\vendor\ptb_urllib3\urllib3\util\retry.py", line 347, in increment
    raise six.reraise(type(error), error, _stacktrace)
  File "D:\Python Projects\Telegram Bot\env\lib\site-packages\telegram\vendor\ptb_urllib3\urllib3\packages\six.py", line 685, in reraise
    raise value.with_traceback(tb)
  File "D:\Python Projects\Telegram Bot\env\lib\site-packages\telegram\vendor\ptb_urllib3\urllib3\connectionpool.py", line 614, in urlopen
    httplib_response = self._make_request(conn, method, url,
  File "D:\Python Projects\Telegram Bot\env\lib\site-packages\telegram\vendor\ptb_urllib3\urllib3\connectionpool.py", line 402, in _make_request
    six.raise_from(e, None)
  File "<string>", line 2, in raise_from
  File "D:\Python Projects\Telegram Bot\env\lib\site-packages\telegram\vendor\ptb_urllib3\urllib3\connectionpool.py", line 398, in _make_request
    httplib_response = conn.getresponse()
  File "C:\Users\olexa\AppData\Local\Programs\Python\Python310\lib\http\client.py", line 1374, in getresponse
    response.begin()
  File "C:\Users\olexa\AppData\Local\Programs\Python\Python310\lib\http\client.py", line 318, in begin
    version, status, reason = self._read_status()
  File "C:\Users\olexa\AppData\Local\Programs\Python\Python310\lib\http\client.py", line 287, in _read_status
    raise RemoteDisconnected("Remote end closed connection without"
telegram.vendor.ptb_urllib3.urllib3.exceptions.ProtocolError: ('Connection aborted.', RemoteDisconnected('Remote end closed connection without response'))

The above exception was the direct cause of the following exception:

Traceback (most recent call last):
  File "D:\Python Projects\Telegram Bot\env\lib\site-packages\telegram\ext\updater.py", line 646, in _network_loop_retry
    if not action_cb():
  File "D:\Python Projects\Telegram Bot\env\lib\site-packages\telegram\ext\updater.py", line 597, in polling_action_cb
    updates = self.bot.get_updates(
  File "D:\Python Projects\Telegram Bot\env\lib\site-packages\telegram\ext\extbot.py", line 224, in get_updates
    updates = super().get_updates(
  File "D:\Python Projects\Telegram Bot\env\lib\site-packages\telegram\bot.py", line 130, in decorator
    result = func(*args, **kwargs)
  File "D:\Python Projects\Telegram Bot\env\lib\site-packages\telegram\bot.py", line 3054, in get_updates
    self._post(
  File "D:\Python Projects\Telegram Bot\env\lib\site-packages\telegram\bot.py", line 295, in _post
    return self.request.post(
  File "D:\Python Projects\Telegram Bot\env\lib\site-packages\telegram\utils\request.py", line 361, in post
    result = self._request_wrapper(
  File "D:\Python Projects\Telegram Bot\env\lib\site-packages\telegram\utils\request.py", line 265, in _request_wrapper
    raise NetworkError(f'urllib3 HTTPError {error}') from error
telegram.error.NetworkError: urllib3 HTTPError ('Connection aborted.', RemoteDisconnected('Remote end closed connection without response'))
06/16/2022 05:37:43 PM: Retrying (Retry(total=2, connect=None, read=None, redirect=None)) after connection broken by 'NewConnectionError('<telegram.vendor.ptb_urllib3.urllib3.connection.VerifiedHTTPSConnection object at 0x00000188FF045990>: Failed to establish a new connection: [Errno 11001] getaddrinfo failed')': /bot5289743701:AAHakRDehtSxxEY5zIMDLlFHyPlJ6qYhmmU/getUpdates
06/16/2022 05:37:44 PM: Retrying (Retry(total=1, connect=None, read=None, redirect=None)) after connection broken by 'NewConnectionError('<telegram.vendor.ptb_urllib3.urllib3.connection.VerifiedHTTPSConnection object at 0x00000188FF0459C0>: Failed to establish a new connection: [Errno 11001] getaddrinfo failed')': /bot5289743701:AAHakRDehtSxxEY5zIMDLlFHyPlJ6qYhmmU/getUpdates
06/16/2022 05:37:44 PM: Retrying (Retry(total=0, connect=None, read=None, redirect=None)) after connection broken by 'NewConnectionError('<telegram.vendor.ptb_urllib3.urllib3.connection.VerifiedHTTPSConnection object at 0x00000188FF045BA0>: Failed to establish a new connection: [Errno 11001] getaddrinfo failed')': /bot5289743701:AAHakRDehtSxxEY5zIMDLlFHyPlJ6qYhmmU/getUpdates
06/16/2022 05:37:44 PM: Error while getting Updates: urllib3 HTTPError HTTPSConnectionPool(host='api.telegram.org', port=443): Max retries exceeded with url: /bot5289743701:AAHakRDehtSxxEY5zIMDLlFHyPlJ6qYhmmU/getUpdates (Caused by NewConnectionError('<telegram.vendor.ptb_urllib3.urllib3.connection.VerifiedHTTPSConnection object at 0x00000188FF0458D0>: Failed to establish a new connection: [Errno 11001] getaddrinfo failed'))
06/16/2022 05:37:44 PM: No error handlers are registered, logging exception.
Traceback (most recent call last):
  File "D:\Python Projects\Telegram Bot\env\lib\site-packages\telegram\vendor\ptb_urllib3\urllib3\connection.py", line 140, in _new_conn
    conn = connection.create_connection(
  File "D:\Python Projects\Telegram Bot\env\lib\site-packages\telegram\vendor\ptb_urllib3\urllib3\util\connection.py", line 60, in create_connection
    for res in socket.getaddrinfo(host, port, family, socket.SOCK_STREAM):
  File "C:\Users\olexa\AppData\Local\Programs\Python\Python310\lib\socket.py", line 955, in getaddrinfo
    for res in _socket.getaddrinfo(host, port, family, type, proto, flags):
socket.gaierror: [Errno 11001] getaddrinfo failed

During handling of the above exception, another exception occurred:

Traceback (most recent call last):
  File "D:\Python Projects\Telegram Bot\env\lib\site-packages\telegram\vendor\ptb_urllib3\urllib3\connectionpool.py", line 614, in urlopen
    httplib_response = self._make_request(conn, method, url,
  File "D:\Python Projects\Telegram Bot\env\lib\site-packages\telegram\vendor\ptb_urllib3\urllib3\connectionpool.py", line 360, in _make_request
    self._validate_conn(conn)
  File "D:\Python Projects\Telegram Bot\env\lib\site-packages\telegram\vendor\ptb_urllib3\urllib3\connectionpool.py", line 857, in _validate_conn
    super(HTTPSConnectionPool, self)._validate_conn(conn)
  File "D:\Python Projects\Telegram Bot\env\lib\site-packages\telegram\vendor\ptb_urllib3\urllib3\connectionpool.py", line 289, in _validate_conn
    conn.connect()
  File "D:\Python Projects\Telegram Bot\env\lib\site-packages\telegram\vendor\ptb_urllib3\urllib3\connection.py", line 284, in connect
    conn = self._new_conn()
  File "D:\Python Projects\Telegram Bot\env\lib\site-packages\telegram\vendor\ptb_urllib3\urllib3\connection.py", line 149, in _new_conn
    raise NewConnectionError(
telegram.vendor.ptb_urllib3.urllib3.exceptions.NewConnectionError: <telegram.vendor.ptb_urllib3.urllib3.connection.VerifiedHTTPSConnection object at 0x00000188FF0458D0>: Failed to establish a new connection: [Errno 11001] getaddrinfo failed

During handling of the above exception, another exception occurred:

Traceback (most recent call last):
  File "D:\Python Projects\Telegram Bot\env\lib\site-packages\telegram\utils\request.py", line 259, in _request_wrapper
    resp = self._con_pool.request(*args, **kwargs)
  File "D:\Python Projects\Telegram Bot\env\lib\site-packages\telegram\vendor\ptb_urllib3\urllib3\request.py", line 68, in request
    return self.request_encode_body(method, url, fields=fields,
  File "D:\Python Projects\Telegram Bot\env\lib\site-packages\telegram\vendor\ptb_urllib3\urllib3\request.py", line 148, in request_encode_body
    return self.urlopen(method, url, **extra_kw)
  File "D:\Python Projects\Telegram Bot\env\lib\site-packages\telegram\vendor\ptb_urllib3\urllib3\poolmanager.py", line 244, in urlopen
    response = conn.urlopen(method, u.request_uri, **kw)
  File "D:\Python Projects\Telegram Bot\env\lib\site-packages\telegram\vendor\ptb_urllib3\urllib3\connectionpool.py", line 691, in urlopen
    return self.urlopen(method, url, body, headers, retries,
  File "D:\Python Projects\Telegram Bot\env\lib\site-packages\telegram\vendor\ptb_urllib3\urllib3\connectionpool.py", line 691, in urlopen
    return self.urlopen(method, url, body, headers, retries,
  File "D:\Python Projects\Telegram Bot\env\lib\site-packages\telegram\vendor\ptb_urllib3\urllib3\connectionpool.py", line 691, in urlopen
    return self.urlopen(method, url, body, headers, retries,
  File "D:\Python Projects\Telegram Bot\env\lib\site-packages\telegram\vendor\ptb_urllib3\urllib3\connectionpool.py", line 665, in urlopen
    retries = retries.increment(method, url, error=e, _pool=self,
  File "D:\Python Projects\Telegram Bot\env\lib\site-packages\telegram\vendor\ptb_urllib3\urllib3\util\retry.py", line 376, in increment
    raise MaxRetryError(_pool, url, error or ResponseError(cause))
telegram.vendor.ptb_urllib3.urllib3.exceptions.MaxRetryError: HTTPSConnectionPool(host='api.telegram.org', port=443): Max retries exceeded with url: /bot5289743701:AAHakRDehtSxxEY5zIMDLlFHyPlJ6qYhmmU/getUpdates (Caused by NewConnectionError('<telegram.vendor.ptb_urllib3.urllib3.connection.VerifiedHTTPSConnection object at 0x00000188FF0458D0>: Failed to establish a new connection: [Errno 11001] getaddrinfo failed'))

The above exception was the direct cause of the following exception:

Traceback (most recent call last):
  File "D:\Python Projects\Telegram Bot\env\lib\site-packages\telegram\ext\updater.py", line 646, in _network_loop_retry
    if not action_cb():
  File "D:\Python Projects\Telegram Bot\env\lib\site-packages\telegram\ext\updater.py", line 597, in polling_action_cb
    updates = self.bot.get_updates(
  File "D:\Python Projects\Telegram Bot\env\lib\site-packages\telegram\ext\extbot.py", line 224, in get_updates
    updates = super().get_updates(
  File "D:\Python Projects\Telegram Bot\env\lib\site-packages\telegram\bot.py", line 130, in decorator
    result = func(*args, **kwargs)
  File "D:\Python Projects\Telegram Bot\env\lib\site-packages\telegram\bot.py", line 3054, in get_updates
    self._post(
  File "D:\Python Projects\Telegram Bot\env\lib\site-packages\telegram\bot.py", line 295, in _post
    return self.request.post(
  File "D:\Python Projects\Telegram Bot\env\lib\site-packages\telegram\utils\request.py", line 361, in post
    result = self._request_wrapper(
  File "D:\Python Projects\Telegram Bot\env\lib\site-packages\telegram\utils\request.py", line 265, in _request_wrapper
    raise NetworkError(f'urllib3 HTTPError {error}') from error
telegram.error.NetworkError: urllib3 HTTPError HTTPSConnectionPool(host='api.telegram.org', port=443): Max retries exceeded with url: /bot5289743701:AAHakRDehtSxxEY5zIMDLlFHyPlJ6qYhmmU/getUpdates (Caused by NewConnectionError('<telegram.vendor.ptb_urllib3.urllib3.connection.VerifiedHTTPSConnection object at 0x00000188FF0458D0>: Failed to establish a new connection: [Errno 11001] getaddrinfo failed'))
06/16/2022 05:37:45 PM: Retrying (Retry(total=2, connect=None, read=None, redirect=None)) after connection broken by 'NewConnectionError('<telegram.vendor.ptb_urllib3.urllib3.connection.VerifiedHTTPSConnection object at 0x00000188FF045F30>: Failed to establish a new connection: [Errno 11001] getaddrinfo failed')': /bot5289743701:AAHakRDehtSxxEY5zIMDLlFHyPlJ6qYhmmU/getUpdates
06/16/2022 05:38:07 PM: Retrying (Retry(total=1, connect=None, read=None, redirect=None)) after connection broken by 'NewConnectionError('<telegram.vendor.ptb_urllib3.urllib3.connection.VerifiedHTTPSConnection object at 0x00000188FF046050>: Failed to establish a new connection: [Errno 11001] getaddrinfo failed')': /bot5289743701:AAHakRDehtSxxEY5zIMDLlFHyPlJ6qYhmmU/getUpdates
06/16/2022 05:38:32 PM: Retrying (Retry(total=2, connect=None, read=None, redirect=None)) after connection broken by 'ConnectTimeoutError(<telegram.vendor.ptb_urllib3.urllib3.connection.VerifiedHTTPSConnection object at 0x00000188FF045AE0>, 'Connection to api.telegram.org timed out. (connect timeout=5.0)')': /bot5289743701:AAHakRDehtSxxEY5zIMDLlFHyPlJ6qYhmmU/getUpdates
06/16/2022 06:23:49 PM: No error handlers are registered, logging exception.
Traceback (most recent call last):
  File "D:\Python Projects\Telegram Bot\env\lib\site-packages\sqlalchemy\engine\base.py", line 1819, in _execute_context
    self.dialect.do_execute(
  File "D:\Python Projects\Telegram Bot\env\lib\site-packages\sqlalchemy\engine\default.py", line 732, in do_execute
    cursor.execute(statement, parameters)
psycopg2.OperationalError: terminating connection due to administrator command
SSL connection has been closed unexpectedly


The above exception was the direct cause of the following exception:

Traceback (most recent call last):
  File "D:\Python Projects\Telegram Bot\env\lib\site-packages\telegram\ext\utils\promise.py", line 96, in run
    self._result = self.pooled_function(*self.args, **self.kwargs)
  File "D:\Python Projects\Telegram Bot\main.py", line 850, in get_info
    fields = db_ops.get_fieldnames_for_tables(user.table_group_name, tablegroups_path)
  File "D:\Python Projects\Telegram Bot\database_operations\db_ops.py", line 398, in get_fieldnames_for_tables
    tablenames = return_tablenames(dbName)
  File "D:\Python Projects\Telegram Bot\database_operations\db_ops.py", line 62, in return_tablenames
    pragma = conn.execute(f"SELECT table_name from information_schema.tables where table_type = 'BASE TABLE' and table_schema = '{dbName}';")
  File "D:\Python Projects\Telegram Bot\env\lib\site-packages\sqlalchemy\engine\base.py", line 1291, in execute
    return self._exec_driver_sql(
  File "D:\Python Projects\Telegram Bot\env\lib\site-packages\sqlalchemy\engine\base.py", line 1595, in _exec_driver_sql
    ret = self._execute_context(
  File "D:\Python Projects\Telegram Bot\env\lib\site-packages\sqlalchemy\engine\base.py", line 1862, in _execute_context
    self._handle_dbapi_exception(
  File "D:\Python Projects\Telegram Bot\env\lib\site-packages\sqlalchemy\engine\base.py", line 2043, in _handle_dbapi_exception
    util.raise_(
  File "D:\Python Projects\Telegram Bot\env\lib\site-packages\sqlalchemy\util\compat.py", line 207, in raise_
    raise exception
  File "D:\Python Projects\Telegram Bot\env\lib\site-packages\sqlalchemy\engine\base.py", line 1819, in _execute_context
    self.dialect.do_execute(
  File "D:\Python Projects\Telegram Bot\env\lib\site-packages\sqlalchemy\engine\default.py", line 732, in do_execute
    cursor.execute(statement, parameters)
sqlalchemy.exc.OperationalError: (psycopg2.OperationalError) terminating connection due to administrator command
SSL connection has been closed unexpectedly

[SQL: SELECT table_name from information_schema.tables where table_type = 'BASE TABLE' and table_schema = 'osint_database_v4';]
(Background on this error at: https://sqlalche.me/e/14/e3q8)
06/16/2022 06:24:05 PM: Promise function raised exception
Traceback (most recent call last):
  File "D:\Python Projects\Telegram Bot\env\lib\site-packages\sqlalchemy\engine\base.py", line 1819, in _execute_context
    self.dialect.do_execute(
  File "D:\Python Projects\Telegram Bot\env\lib\site-packages\sqlalchemy\engine\default.py", line 732, in do_execute
    cursor.execute(statement, parameters)
psycopg2.OperationalError: terminating connection due to administrator command
SSL connection has been closed unexpectedly


The above exception was the direct cause of the following exception:

Traceback (most recent call last):
  File "D:\Python Projects\Telegram Bot\env\lib\site-packages\telegram\ext\conversationhandler.py", line 474, in _resolve_promise
    res = new_state.result(0)
  File "D:\Python Projects\Telegram Bot\env\lib\site-packages\telegram\ext\utils\promise.py", line 132, in result
    raise self._exception  # pylint: disable=raising-bad-type
  File "D:\Python Projects\Telegram Bot\env\lib\site-packages\telegram\ext\utils\promise.py", line 96, in run
    self._result = self.pooled_function(*self.args, **self.kwargs)
  File "D:\Python Projects\Telegram Bot\main.py", line 850, in get_info
    fields = db_ops.get_fieldnames_for_tables(user.table_group_name, tablegroups_path)
  File "D:\Python Projects\Telegram Bot\database_operations\db_ops.py", line 398, in get_fieldnames_for_tables
    tablenames = return_tablenames(dbName)
  File "D:\Python Projects\Telegram Bot\database_operations\db_ops.py", line 62, in return_tablenames
    pragma = conn.execute(f"SELECT table_name from information_schema.tables where table_type = 'BASE TABLE' and table_schema = '{dbName}';")
  File "D:\Python Projects\Telegram Bot\env\lib\site-packages\sqlalchemy\engine\base.py", line 1291, in execute
    return self._exec_driver_sql(
  File "D:\Python Projects\Telegram Bot\env\lib\site-packages\sqlalchemy\engine\base.py", line 1595, in _exec_driver_sql
    ret = self._execute_context(
  File "D:\Python Projects\Telegram Bot\env\lib\site-packages\sqlalchemy\engine\base.py", line 1862, in _execute_context
    self._handle_dbapi_exception(
  File "D:\Python Projects\Telegram Bot\env\lib\site-packages\sqlalchemy\engine\base.py", line 2043, in _handle_dbapi_exception
    util.raise_(
  File "D:\Python Projects\Telegram Bot\env\lib\site-packages\sqlalchemy\util\compat.py", line 207, in raise_
    raise exception
  File "D:\Python Projects\Telegram Bot\env\lib\site-packages\sqlalchemy\engine\base.py", line 1819, in _execute_context
    self.dialect.do_execute(
  File "D:\Python Projects\Telegram Bot\env\lib\site-packages\sqlalchemy\engine\default.py", line 732, in do_execute
    cursor.execute(statement, parameters)
sqlalchemy.exc.OperationalError: (psycopg2.OperationalError) terminating connection due to administrator command
SSL connection has been closed unexpectedly

[SQL: SELECT table_name from information_schema.tables where table_type = 'BASE TABLE' and table_schema = 'osint_database_v4';]
(Background on this error at: https://sqlalche.me/e/14/e3q8)
06/16/2022 06:24:05 PM: (psycopg2.OperationalError) terminating connection due to administrator command
SSL connection has been closed unexpectedly

[SQL: SELECT table_name from information_schema.tables where table_type = 'BASE TABLE' and table_schema = 'osint_database_v4';]
(Background on this error at: https://sqlalche.me/e/14/e3q8)
Traceback (most recent call last):
  File "D:\Python Projects\Telegram Bot\env\lib\site-packages\sqlalchemy\engine\base.py", line 1819, in _execute_context
    self.dialect.do_execute(
  File "D:\Python Projects\Telegram Bot\env\lib\site-packages\sqlalchemy\engine\default.py", line 732, in do_execute
    cursor.execute(statement, parameters)
psycopg2.OperationalError: terminating connection due to administrator command
SSL connection has been closed unexpectedly


The above exception was the direct cause of the following exception:

Traceback (most recent call last):
  File "D:\Python Projects\Telegram Bot\env\lib\site-packages\telegram\ext\conversationhandler.py", line 474, in _resolve_promise
    res = new_state.result(0)
  File "D:\Python Projects\Telegram Bot\env\lib\site-packages\telegram\ext\utils\promise.py", line 132, in result
    raise self._exception  # pylint: disable=raising-bad-type
  File "D:\Python Projects\Telegram Bot\env\lib\site-packages\telegram\ext\utils\promise.py", line 96, in run
    self._result = self.pooled_function(*self.args, **self.kwargs)
  File "D:\Python Projects\Telegram Bot\main.py", line 850, in get_info
    fields = db_ops.get_fieldnames_for_tables(user.table_group_name, tablegroups_path)
  File "D:\Python Projects\Telegram Bot\database_operations\db_ops.py", line 398, in get_fieldnames_for_tables
    tablenames = return_tablenames(dbName)
  File "D:\Python Projects\Telegram Bot\database_operations\db_ops.py", line 62, in return_tablenames
    pragma = conn.execute(f"SELECT table_name from information_schema.tables where table_type = 'BASE TABLE' and table_schema = '{dbName}';")
  File "D:\Python Projects\Telegram Bot\env\lib\site-packages\sqlalchemy\engine\base.py", line 1291, in execute
    return self._exec_driver_sql(
  File "D:\Python Projects\Telegram Bot\env\lib\site-packages\sqlalchemy\engine\base.py", line 1595, in _exec_driver_sql
    ret = self._execute_context(
  File "D:\Python Projects\Telegram Bot\env\lib\site-packages\sqlalchemy\engine\base.py", line 1862, in _execute_context
    self._handle_dbapi_exception(
  File "D:\Python Projects\Telegram Bot\env\lib\site-packages\sqlalchemy\engine\base.py", line 2043, in _handle_dbapi_exception
    util.raise_(
  File "D:\Python Projects\Telegram Bot\env\lib\site-packages\sqlalchemy\util\compat.py", line 207, in raise_
    raise exception
  File "D:\Python Projects\Telegram Bot\env\lib\site-packages\sqlalchemy\engine\base.py", line 1819, in _execute_context
    self.dialect.do_execute(
  File "D:\Python Projects\Telegram Bot\env\lib\site-packages\sqlalchemy\engine\default.py", line 732, in do_execute
    cursor.execute(statement, parameters)
sqlalchemy.exc.OperationalError: (psycopg2.OperationalError) terminating connection due to administrator command
SSL connection has been closed unexpectedly

[SQL: SELECT table_name from information_schema.tables where table_type = 'BASE TABLE' and table_schema = 'osint_database_v4';]
(Background on this error at: https://sqlalche.me/e/14/e3q8)
06/16/2022 06:54:09 PM: No error handlers are registered, logging exception.
Traceback (most recent call last):
  File "D:\Python Projects\Telegram Bot\env\lib\site-packages\sqlalchemy\engine\base.py", line 1819, in _execute_context
    self.dialect.do_execute(
  File "D:\Python Projects\Telegram Bot\env\lib\site-packages\sqlalchemy\engine\default.py", line 732, in do_execute
    cursor.execute(statement, parameters)
psycopg2.OperationalError: terminating connection due to administrator command
SSL connection has been closed unexpectedly


The above exception was the direct cause of the following exception:

Traceback (most recent call last):
  File "D:\Python Projects\Telegram Bot\env\lib\site-packages\telegram\ext\utils\promise.py", line 96, in run
    self._result = self.pooled_function(*self.args, **self.kwargs)
  File "D:\Python Projects\Telegram Bot\main.py", line 850, in get_info
    fields = db_ops.get_fieldnames_for_tables(user.table_group_name, tablegroups_path)
  File "D:\Python Projects\Telegram Bot\database_operations\db_ops.py", line 398, in get_fieldnames_for_tables
    tablenames = return_tablenames(dbName)
  File "D:\Python Projects\Telegram Bot\database_operations\db_ops.py", line 62, in return_tablenames
    pragma = conn.execute(f"SELECT table_name from information_schema.tables where table_type = 'BASE TABLE' and table_schema = '{dbName}';")
  File "D:\Python Projects\Telegram Bot\env\lib\site-packages\sqlalchemy\engine\base.py", line 1291, in execute
    return self._exec_driver_sql(
  File "D:\Python Projects\Telegram Bot\env\lib\site-packages\sqlalchemy\engine\base.py", line 1595, in _exec_driver_sql
    ret = self._execute_context(
  File "D:\Python Projects\Telegram Bot\env\lib\site-packages\sqlalchemy\engine\base.py", line 1862, in _execute_context
    self._handle_dbapi_exception(
  File "D:\Python Projects\Telegram Bot\env\lib\site-packages\sqlalchemy\engine\base.py", line 2043, in _handle_dbapi_exception
    util.raise_(
  File "D:\Python Projects\Telegram Bot\env\lib\site-packages\sqlalchemy\util\compat.py", line 207, in raise_
    raise exception
  File "D:\Python Projects\Telegram Bot\env\lib\site-packages\sqlalchemy\engine\base.py", line 1819, in _execute_context
    self.dialect.do_execute(
  File "D:\Python Projects\Telegram Bot\env\lib\site-packages\sqlalchemy\engine\default.py", line 732, in do_execute
    cursor.execute(statement, parameters)
sqlalchemy.exc.OperationalError: (psycopg2.OperationalError) terminating connection due to administrator command
SSL connection has been closed unexpectedly

[SQL: SELECT table_name from information_schema.tables where table_type = 'BASE TABLE' and table_schema = 'osint_database_v4';]
(Background on this error at: https://sqlalche.me/e/14/e3q8)
06/16/2022 06:54:30 PM: Promise function raised exception
Traceback (most recent call last):
  File "D:\Python Projects\Telegram Bot\env\lib\site-packages\sqlalchemy\engine\base.py", line 1819, in _execute_context
    self.dialect.do_execute(
  File "D:\Python Projects\Telegram Bot\env\lib\site-packages\sqlalchemy\engine\default.py", line 732, in do_execute
    cursor.execute(statement, parameters)
psycopg2.OperationalError: terminating connection due to administrator command
SSL connection has been closed unexpectedly


The above exception was the direct cause of the following exception:

Traceback (most recent call last):
  File "D:\Python Projects\Telegram Bot\env\lib\site-packages\telegram\ext\conversationhandler.py", line 474, in _resolve_promise
    res = new_state.result(0)
  File "D:\Python Projects\Telegram Bot\env\lib\site-packages\telegram\ext\utils\promise.py", line 132, in result
    raise self._exception  # pylint: disable=raising-bad-type
  File "D:\Python Projects\Telegram Bot\env\lib\site-packages\telegram\ext\utils\promise.py", line 96, in run
    self._result = self.pooled_function(*self.args, **self.kwargs)
  File "D:\Python Projects\Telegram Bot\main.py", line 850, in get_info
    fields = db_ops.get_fieldnames_for_tables(user.table_group_name, tablegroups_path)
  File "D:\Python Projects\Telegram Bot\database_operations\db_ops.py", line 398, in get_fieldnames_for_tables
    tablenames = return_tablenames(dbName)
  File "D:\Python Projects\Telegram Bot\database_operations\db_ops.py", line 62, in return_tablenames
    pragma = conn.execute(f"SELECT table_name from information_schema.tables where table_type = 'BASE TABLE' and table_schema = '{dbName}';")
  File "D:\Python Projects\Telegram Bot\env\lib\site-packages\sqlalchemy\engine\base.py", line 1291, in execute
    return self._exec_driver_sql(
  File "D:\Python Projects\Telegram Bot\env\lib\site-packages\sqlalchemy\engine\base.py", line 1595, in _exec_driver_sql
    ret = self._execute_context(
  File "D:\Python Projects\Telegram Bot\env\lib\site-packages\sqlalchemy\engine\base.py", line 1862, in _execute_context
    self._handle_dbapi_exception(
  File "D:\Python Projects\Telegram Bot\env\lib\site-packages\sqlalchemy\engine\base.py", line 2043, in _handle_dbapi_exception
    util.raise_(
  File "D:\Python Projects\Telegram Bot\env\lib\site-packages\sqlalchemy\util\compat.py", line 207, in raise_
    raise exception
  File "D:\Python Projects\Telegram Bot\env\lib\site-packages\sqlalchemy\engine\base.py", line 1819, in _execute_context
    self.dialect.do_execute(
  File "D:\Python Projects\Telegram Bot\env\lib\site-packages\sqlalchemy\engine\default.py", line 732, in do_execute
    cursor.execute(statement, parameters)
sqlalchemy.exc.OperationalError: (psycopg2.OperationalError) terminating connection due to administrator command
SSL connection has been closed unexpectedly

[SQL: SELECT table_name from information_schema.tables where table_type = 'BASE TABLE' and table_schema = 'osint_database_v4';]
(Background on this error at: https://sqlalche.me/e/14/e3q8)
06/16/2022 06:54:30 PM: (psycopg2.OperationalError) terminating connection due to administrator command
SSL connection has been closed unexpectedly

[SQL: SELECT table_name from information_schema.tables where table_type = 'BASE TABLE' and table_schema = 'osint_database_v4';]
(Background on this error at: https://sqlalche.me/e/14/e3q8)
Traceback (most recent call last):
  File "D:\Python Projects\Telegram Bot\env\lib\site-packages\sqlalchemy\engine\base.py", line 1819, in _execute_context
    self.dialect.do_execute(
  File "D:\Python Projects\Telegram Bot\env\lib\site-packages\sqlalchemy\engine\default.py", line 732, in do_execute
    cursor.execute(statement, parameters)
psycopg2.OperationalError: terminating connection due to administrator command
SSL connection has been closed unexpectedly


The above exception was the direct cause of the following exception:

Traceback (most recent call last):
  File "D:\Python Projects\Telegram Bot\env\lib\site-packages\telegram\ext\conversationhandler.py", line 474, in _resolve_promise
    res = new_state.result(0)
  File "D:\Python Projects\Telegram Bot\env\lib\site-packages\telegram\ext\utils\promise.py", line 132, in result
    raise self._exception  # pylint: disable=raising-bad-type
  File "D:\Python Projects\Telegram Bot\env\lib\site-packages\telegram\ext\utils\promise.py", line 96, in run
    self._result = self.pooled_function(*self.args, **self.kwargs)
  File "D:\Python Projects\Telegram Bot\main.py", line 850, in get_info
    fields = db_ops.get_fieldnames_for_tables(user.table_group_name, tablegroups_path)
  File "D:\Python Projects\Telegram Bot\database_operations\db_ops.py", line 398, in get_fieldnames_for_tables
    tablenames = return_tablenames(dbName)
  File "D:\Python Projects\Telegram Bot\database_operations\db_ops.py", line 62, in return_tablenames
    pragma = conn.execute(f"SELECT table_name from information_schema.tables where table_type = 'BASE TABLE' and table_schema = '{dbName}';")
  File "D:\Python Projects\Telegram Bot\env\lib\site-packages\sqlalchemy\engine\base.py", line 1291, in execute
    return self._exec_driver_sql(
  File "D:\Python Projects\Telegram Bot\env\lib\site-packages\sqlalchemy\engine\base.py", line 1595, in _exec_driver_sql
    ret = self._execute_context(
  File "D:\Python Projects\Telegram Bot\env\lib\site-packages\sqlalchemy\engine\base.py", line 1862, in _execute_context
    self._handle_dbapi_exception(
  File "D:\Python Projects\Telegram Bot\env\lib\site-packages\sqlalchemy\engine\base.py", line 2043, in _handle_dbapi_exception
    util.raise_(
  File "D:\Python Projects\Telegram Bot\env\lib\site-packages\sqlalchemy\util\compat.py", line 207, in raise_
    raise exception
  File "D:\Python Projects\Telegram Bot\env\lib\site-packages\sqlalchemy\engine\base.py", line 1819, in _execute_context
    self.dialect.do_execute(
  File "D:\Python Projects\Telegram Bot\env\lib\site-packages\sqlalchemy\engine\default.py", line 732, in do_execute
    cursor.execute(statement, parameters)
sqlalchemy.exc.OperationalError: (psycopg2.OperationalError) terminating connection due to administrator command
SSL connection has been closed unexpectedly

[SQL: SELECT table_name from information_schema.tables where table_type = 'BASE TABLE' and table_schema = 'osint_database_v4';]
(Background on this error at: https://sqlalche.me/e/14/e3q8)
06/17/2022 02:52:23 PM: Retrying (Retry(total=2, connect=None, read=None, redirect=None)) after connection broken by 'ConnectTimeoutError(<telegram.vendor.ptb_urllib3.urllib3.connection.VerifiedHTTPSConnection object at 0x000001ADBDFA5F30>, 'Connection to api.telegram.org timed out. (connect timeout=5.0)')': /bot5289743701:AAHakRDehtSxxEY5zIMDLlFHyPlJ6qYhmmU/getUpdates
06/17/2022 02:52:28 PM: Retrying (Retry(total=1, connect=None, read=None, redirect=None)) after connection broken by 'ConnectTimeoutError(<telegram.vendor.ptb_urllib3.urllib3.connection.VerifiedHTTPSConnection object at 0x000001ADBDFA4D60>, 'Connection to api.telegram.org timed out. (connect timeout=5.0)')': /bot5289743701:AAHakRDehtSxxEY5zIMDLlFHyPlJ6qYhmmU/getUpdates
06/17/2022 02:53:02 PM: Retrying (Retry(total=2, connect=None, read=None, redirect=None)) after connection broken by 'ConnectTimeoutError(<telegram.vendor.ptb_urllib3.urllib3.connection.VerifiedHTTPSConnection object at 0x000001ADBDFA63B0>, 'Connection to api.telegram.org timed out. (connect timeout=5.0)')': /bot5289743701:AAHakRDehtSxxEY5zIMDLlFHyPlJ6qYhmmU/getUpdates
06/17/2022 02:53:07 PM: Retrying (Retry(total=1, connect=None, read=None, redirect=None)) after connection broken by 'ConnectTimeoutError(<telegram.vendor.ptb_urllib3.urllib3.connection.VerifiedHTTPSConnection object at 0x000001ADBDFA6440>, 'Connection to api.telegram.org timed out. (connect timeout=5.0)')': /bot5289743701:AAHakRDehtSxxEY5zIMDLlFHyPlJ6qYhmmU/getUpdates
06/17/2022 02:53:12 PM: Retrying (Retry(total=0, connect=None, read=None, redirect=None)) after connection broken by 'ConnectTimeoutError(<telegram.vendor.ptb_urllib3.urllib3.connectionpool.HTTPSConnectionPool object at 0x000001ADBDFA4190>, 'Connect timed out. (connect timeout=5.0)')': /bot5289743701:AAHakRDehtSxxEY5zIMDLlFHyPlJ6qYhmmU/getUpdates
06/17/2022 05:46:47 PM: (psycopg2.errors.StringDataRightTruncation) value too long for type character varying(12)

[SQL: INSERT INTO "Інформація про фізичну особу" ("соцмережі", "серія", "ДН", "паспорт", "посада", "ел.пошта", "телефон", "ПІБ", "ІНПП", "адреса", "місце_роботи") VALUES (%(соцмережі)s, %(серія)s, %(ДН)s, %(паспорт)s, %(посада)s, %(ел.пошта)s, %(телефон)s, %(ПІБ)s, %(ІНПП)s, %(адреса)s, %(місце_роботи)s)]
[parameters: ({'соцмережі': None, 'серія': None, 'ДН': datetime.datetime(1969, 6, 17, 0, 0), 'паспорт': None, 'посада': None, 'ел.пошта': None, 'телефон': None, 'ПІБ': 'Бодак Орест Андрійович', 'ІНПП': None, 'адреса': 'м Івано-Франківськ, ВУЛ.БАРВИСТА, б.3, кв.2', 'місце_роботи': None}, {'соцмережі': None, 'серія': None, 'ДН': datetime.datetime(1957, 2, 4, 0, 0), 'паспорт': None, 'посада': None, 'ел.пошта': None, 'телефон': None, 'ПІБ': 'Ситайло Валентина Петрівна', 'ІНПП': None, 'адреса': 'м Івано-Франківськ, ВУЛ.БАРВИСТА, б.14', 'місце_роботи': None}, {'соцмережі': None, 'серія': None, 'ДН': datetime.datetime(1981, 7, 26, 0, 0), 'паспорт': None, 'посада': None, 'ел.пошта': None, 'телефон': None, 'ПІБ': 'Ситайло Олена Миколаївна', 'ІНПП': None, 'адреса': 'м Івано-Франківськ, ВУЛ.БАРВИСТА, б.14', 'місце_роботи': None}, {'соцмережі': None, 'серія': None, 'ДН': datetime.datetime(1983, 2, 26, 0, 0), 'паспорт': None, 'посада': None, 'ел.пошта': None, 'телефон': None, 'ПІБ': 'Ситайло Юрій Володимирович', 'ІНПП': None, 'адреса': 'м Івано-Франківськ, ВУЛ.БАРВИСТА, б.14', 'місце_роботи': None}, {'соцмережі': None, 'серія': None, 'ДН': datetime.datetime(1954, 8, 19, 0, 0), 'паспорт': None, 'посада': None, 'ел.пошта': None, 'телефон': None, 'ПІБ': 'Сітайло Микола Олексійович', 'ІНПП': None, 'адреса': 'м Івано-Франківськ, ВУЛ.БАРВИСТА, б.14', 'місце_роботи': None}, {'соцмережі': None, 'серія': None, 'ДН': datetime.datetime(1940, 1, 22, 0, 0), 'паспорт': None, 'посада': None, 'ел.пошта': None, 'телефон': None, 'ПІБ': 'Цебрій Роман Миколайович', 'ІНПП': None, 'адреса': 'м Івано-Франківськ, ВУЛ.БАРВИСТА, б.15, кв.2', 'місце_роботи': None}, {'соцмережі': None, 'серія': None, 'ДН': datetime.datetime(1972, 7, 17, 0, 0), 'паспорт': None, 'посада': None, 'ел.пошта': None, 'телефон': None, 'ПІБ': 'Цебрій Тетяна Петрівна', 'ІНПП': None, 'адреса': 'м Івано-Франківськ, ВУЛ.БАРВИСТА, б.15, кв.2', 'місце_роботи': None}, {'соцмережі': None, 'серія': None, 'ДН': datetime.datetime(1953, 7, 16, 0, 0), 'паспорт': None, 'посада': None, 'ел.пошта': None, 'телефон': None, 'ПІБ': 'Бойчук Марія Олексіївна', 'ІНПП': None, 'адреса': 'м Івано-Франківськ, ВУЛ.БАРВИСТА, б.27', 'місце_роботи': None}  ... displaying 10 of 10000 total bound parameter sets ...  {'соцмережі': None, 'серія': None, 'ДН': datetime.datetime(1975, 7, 6, 0, 0), 'паспорт': None, 'посада': None, 'ел.пошта': None, 'телефон': None, 'ПІБ': 'Васьків Анатолій Петрович', 'ІНПП': None, 'адреса': 'м Івано-Франківськ, ВУЛ.ТРОЛЕЙБУСНА, б.5, кв.105', 'місце_роботи': None}, {'соцмережі': None, 'серія': None, 'ДН': datetime.datetime(1944, 10, 12, 0, 0), 'паспорт': None, 'посада': None, 'ел.пошта': None, 'телефон': None, 'ПІБ': 'Васьків Лідія Ілларіонівна', 'ІНПП': None, 'адреса': 'м Івано-Франківськ, ВУЛ.ТРОЛЕЙБУСНА, б.5, кв.105', 'місце_роботи': None})]
(Background on this error at: https://sqlalche.me/e/14/9h9h)
Traceback (most recent call last):
  File "D:\Python Projects\Telegram Bot\env\lib\site-packages\sqlalchemy\engine\base.py", line 1799, in _execute_context
    self.dialect.do_executemany(
  File "D:\Python Projects\Telegram Bot\env\lib\site-packages\sqlalchemy\dialects\postgresql\psycopg2.py", line 951, in do_executemany
    context._psycopg2_fetched_rows = xtras.execute_values(
  File "D:\Python Projects\Telegram Bot\env\lib\site-packages\psycopg2\extras.py", line 1270, in execute_values
    cur.execute(b''.join(parts))
psycopg2.errors.StringDataRightTruncation: value too long for type character varying(12)


The above exception was the direct cause of the following exception:

Traceback (most recent call last):
  File "D:\Python Projects\Telegram Bot\main.py", line 796, in file_insertion
    msg, columns = parsers.parse_file(file, user.table_group_name, table_name, append)
  File "D:\Python Projects\Telegram Bot\parsers.py", line 347, in parse_file
    columns = parser(file, table_group_name, tablename, append_choice=append_choise)
  File "D:\Python Projects\Telegram Bot\parsers.py", line 384, in parser
    flag = db_ops.upload_data(df, table_group_name, table_name=tablename,
  File "D:\Python Projects\Telegram Bot\database_operations\db_ops.py", line 243, in upload_data
    temp_df.to_sql(table, con=engine, if_exists='append', chunksize=10000, index=False)
  File "D:\Python Projects\Telegram Bot\env\lib\site-packages\pandas\core\generic.py", line 2951, in to_sql
    return sql.to_sql(
  File "D:\Python Projects\Telegram Bot\env\lib\site-packages\pandas\io\sql.py", line 697, in to_sql
    return pandas_sql.to_sql(
  File "D:\Python Projects\Telegram Bot\env\lib\site-packages\pandas\io\sql.py", line 1739, in to_sql
    total_inserted = sql_engine.insert_records(
  File "D:\Python Projects\Telegram Bot\env\lib\site-packages\pandas\io\sql.py", line 1332, in insert_records
    raise err
  File "D:\Python Projects\Telegram Bot\env\lib\site-packages\pandas\io\sql.py", line 1322, in insert_records
    return table.insert(chunksize=chunksize, method=method)
  File "D:\Python Projects\Telegram Bot\env\lib\site-packages\pandas\io\sql.py", line 950, in insert
    num_inserted = exec_insert(conn, keys, chunk_iter)
  File "D:\Python Projects\Telegram Bot\env\lib\site-packages\pandas\io\sql.py", line 857, in _execute_insert
    result = conn.execute(self.table.insert(), data)
  File "D:\Python Projects\Telegram Bot\env\lib\site-packages\sqlalchemy\engine\base.py", line 1306, in execute
    return meth(self, multiparams, params, _EMPTY_EXECUTION_OPTS)
  File "D:\Python Projects\Telegram Bot\env\lib\site-packages\sqlalchemy\sql\elements.py", line 325, in _execute_on_connection
    return connection._execute_clauseelement(
  File "D:\Python Projects\Telegram Bot\env\lib\site-packages\sqlalchemy\engine\base.py", line 1498, in _execute_clauseelement
    ret = self._execute_context(
  File "D:\Python Projects\Telegram Bot\env\lib\site-packages\sqlalchemy\engine\base.py", line 1862, in _execute_context
    self._handle_dbapi_exception(
  File "D:\Python Projects\Telegram Bot\env\lib\site-packages\sqlalchemy\engine\base.py", line 2043, in _handle_dbapi_exception
    util.raise_(
  File "D:\Python Projects\Telegram Bot\env\lib\site-packages\sqlalchemy\util\compat.py", line 207, in raise_
    raise exception
  File "D:\Python Projects\Telegram Bot\env\lib\site-packages\sqlalchemy\engine\base.py", line 1799, in _execute_context
    self.dialect.do_executemany(
  File "D:\Python Projects\Telegram Bot\env\lib\site-packages\sqlalchemy\dialects\postgresql\psycopg2.py", line 951, in do_executemany
    context._psycopg2_fetched_rows = xtras.execute_values(
  File "D:\Python Projects\Telegram Bot\env\lib\site-packages\psycopg2\extras.py", line 1270, in execute_values
    cur.execute(b''.join(parts))
sqlalchemy.exc.DataError: (psycopg2.errors.StringDataRightTruncation) value too long for type character varying(12)

[SQL: INSERT INTO "Інформація про фізичну особу" ("соцмережі", "серія", "ДН", "паспорт", "посада", "ел.пошта", "телефон", "ПІБ", "ІНПП", "адреса", "місце_роботи") VALUES (%(соцмережі)s, %(серія)s, %(ДН)s, %(паспорт)s, %(посада)s, %(ел.пошта)s, %(телефон)s, %(ПІБ)s, %(ІНПП)s, %(адреса)s, %(місце_роботи)s)]
[parameters: ({'соцмережі': None, 'серія': None, 'ДН': datetime.datetime(1969, 6, 17, 0, 0), 'паспорт': None, 'посада': None, 'ел.пошта': None, 'телефон': None, 'ПІБ': 'Бодак Орест Андрійович', 'ІНПП': None, 'адреса': 'м Івано-Франківськ, ВУЛ.БАРВИСТА, б.3, кв.2', 'місце_роботи': None}, {'соцмережі': None, 'серія': None, 'ДН': datetime.datetime(1957, 2, 4, 0, 0), 'паспорт': None, 'посада': None, 'ел.пошта': None, 'телефон': None, 'ПІБ': 'Ситайло Валентина Петрівна', 'ІНПП': None, 'адреса': 'м Івано-Франківськ, ВУЛ.БАРВИСТА, б.14', 'місце_роботи': None}, {'соцмережі': None, 'серія': None, 'ДН': datetime.datetime(1981, 7, 26, 0, 0), 'паспорт': None, 'посада': None, 'ел.пошта': None, 'телефон': None, 'ПІБ': 'Ситайло Олена Миколаївна', 'ІНПП': None, 'адреса': 'м Івано-Франківськ, ВУЛ.БАРВИСТА, б.14', 'місце_роботи': None}, {'соцмережі': None, 'серія': None, 'ДН': datetime.datetime(1983, 2, 26, 0, 0), 'паспорт': None, 'посада': None, 'ел.пошта': None, 'телефон': None, 'ПІБ': 'Ситайло Юрій Володимирович', 'ІНПП': None, 'адреса': 'м Івано-Франківськ, ВУЛ.БАРВИСТА, б.14', 'місце_роботи': None}, {'соцмережі': None, 'серія': None, 'ДН': datetime.datetime(1954, 8, 19, 0, 0), 'паспорт': None, 'посада': None, 'ел.пошта': None, 'телефон': None, 'ПІБ': 'Сітайло Микола Олексійович', 'ІНПП': None, 'адреса': 'м Івано-Франківськ, ВУЛ.БАРВИСТА, б.14', 'місце_роботи': None}, {'соцмережі': None, 'серія': None, 'ДН': datetime.datetime(1940, 1, 22, 0, 0), 'паспорт': None, 'посада': None, 'ел.пошта': None, 'телефон': None, 'ПІБ': 'Цебрій Роман Миколайович', 'ІНПП': None, 'адреса': 'м Івано-Франківськ, ВУЛ.БАРВИСТА, б.15, кв.2', 'місце_роботи': None}, {'соцмережі': None, 'серія': None, 'ДН': datetime.datetime(1972, 7, 17, 0, 0), 'паспорт': None, 'посада': None, 'ел.пошта': None, 'телефон': None, 'ПІБ': 'Цебрій Тетяна Петрівна', 'ІНПП': None, 'адреса': 'м Івано-Франківськ, ВУЛ.БАРВИСТА, б.15, кв.2', 'місце_роботи': None}, {'соцмережі': None, 'серія': None, 'ДН': datetime.datetime(1953, 7, 16, 0, 0), 'паспорт': None, 'посада': None, 'ел.пошта': None, 'телефон': None, 'ПІБ': 'Бойчук Марія Олексіївна', 'ІНПП': None, 'адреса': 'м Івано-Франківськ, ВУЛ.БАРВИСТА, б.27', 'місце_роботи': None}  ... displaying 10 of 10000 total bound parameter sets ...  {'соцмережі': None, 'серія': None, 'ДН': datetime.datetime(1975, 7, 6, 0, 0), 'паспорт': None, 'посада': None, 'ел.пошта': None, 'телефон': None, 'ПІБ': 'Васьків Анатолій Петрович', 'ІНПП': None, 'адреса': 'м Івано-Франківськ, ВУЛ.ТРОЛЕЙБУСНА, б.5, кв.105', 'місце_роботи': None}, {'соцмережі': None, 'серія': None, 'ДН': datetime.datetime(1944, 10, 12, 0, 0), 'паспорт': None, 'посада': None, 'ел.пошта': None, 'телефон': None, 'ПІБ': 'Васьків Лідія Ілларіонівна', 'ІНПП': None, 'адреса': 'м Івано-Франківськ, ВУЛ.ТРОЛЕЙБУСНА, б.5, кв.105', 'місце_роботи': None})]
(Background on this error at: https://sqlalche.me/e/14/9h9h)
06/17/2022 05:59:21 PM: dict is not a sequence
Traceback (most recent call last):
  File "D:\Python Projects\Telegram Bot\main.py", line 946, in parameter_confirmation
    msg = parsers.get_data(tablegroups_path, user)
  File "D:\Python Projects\Telegram Bot\parsers.py", line 486, in get_data
    data, header = db_ops.get_data_from_db(parameter, value, user.table_group_name, path)
  File "D:\Python Projects\Telegram Bot\database_operations\db_ops.py", line 308, in get_data_from_db
    result = conn.execute(f"SELECT COUNT() from '{element}' WHERE {parameter} LIKE %{value}%;").fetchall()
  File "D:\Python Projects\Telegram Bot\env\lib\site-packages\sqlalchemy\engine\base.py", line 1291, in execute
    return self._exec_driver_sql(
  File "D:\Python Projects\Telegram Bot\env\lib\site-packages\sqlalchemy\engine\base.py", line 1595, in _exec_driver_sql
    ret = self._execute_context(
  File "D:\Python Projects\Telegram Bot\env\lib\site-packages\sqlalchemy\engine\base.py", line 1862, in _execute_context
    self._handle_dbapi_exception(
  File "D:\Python Projects\Telegram Bot\env\lib\site-packages\sqlalchemy\engine\base.py", line 2047, in _handle_dbapi_exception
    util.raise_(exc_info[1], with_traceback=exc_info[2])
  File "D:\Python Projects\Telegram Bot\env\lib\site-packages\sqlalchemy\util\compat.py", line 207, in raise_
    raise exception
  File "D:\Python Projects\Telegram Bot\env\lib\site-packages\sqlalchemy\engine\base.py", line 1819, in _execute_context
    self.dialect.do_execute(
  File "D:\Python Projects\Telegram Bot\env\lib\site-packages\sqlalchemy\engine\default.py", line 732, in do_execute
    cursor.execute(statement, parameters)
TypeError: dict is not a sequence
06/17/2022 06:01:19 PM: dict is not a sequence
Traceback (most recent call last):
  File "D:\Python Projects\Telegram Bot\main.py", line 946, in parameter_confirmation
    msg = parsers.get_data(tablegroups_path, user)
  File "D:\Python Projects\Telegram Bot\parsers.py", line 486, in get_data
    data, header = db_ops.get_data_from_db(parameter, value, user.table_group_name, path)
  File "D:\Python Projects\Telegram Bot\database_operations\db_ops.py", line 308, in get_data_from_db
    result = conn.execute(f"SELECT COUNT() from '{element}' WHERE {parameter} LIKE %{value}%;").fetchall()
  File "D:\Python Projects\Telegram Bot\env\lib\site-packages\sqlalchemy\engine\base.py", line 1291, in execute
    return self._exec_driver_sql(
  File "D:\Python Projects\Telegram Bot\env\lib\site-packages\sqlalchemy\engine\base.py", line 1595, in _exec_driver_sql
    ret = self._execute_context(
  File "D:\Python Projects\Telegram Bot\env\lib\site-packages\sqlalchemy\engine\base.py", line 1862, in _execute_context
    self._handle_dbapi_exception(
  File "D:\Python Projects\Telegram Bot\env\lib\site-packages\sqlalchemy\engine\base.py", line 2047, in _handle_dbapi_exception
    util.raise_(exc_info[1], with_traceback=exc_info[2])
  File "D:\Python Projects\Telegram Bot\env\lib\site-packages\sqlalchemy\util\compat.py", line 207, in raise_
    raise exception
  File "D:\Python Projects\Telegram Bot\env\lib\site-packages\sqlalchemy\engine\base.py", line 1819, in _execute_context
    self.dialect.do_execute(
  File "D:\Python Projects\Telegram Bot\env\lib\site-packages\sqlalchemy\engine\default.py", line 732, in do_execute
    cursor.execute(statement, parameters)
TypeError: dict is not a sequence
06/17/2022 06:02:40 PM: (psycopg2.errors.SyntaxError) syntax error at or near "'Інформація про фізичну особу'"
LINE 1: SELECT COUNT() from 'Інформація про фізичну особу' WHERE ПІБ...
                            ^

[SQL: SELECT COUNT() from 'Інформація про фізичну особу' WHERE ПІБ LIKE 'Іванюк Лілія Василівна%%';]
(Background on this error at: https://sqlalche.me/e/14/f405)
Traceback (most recent call last):
  File "D:\Python Projects\Telegram Bot\env\lib\site-packages\sqlalchemy\engine\base.py", line 1819, in _execute_context
    self.dialect.do_execute(
  File "D:\Python Projects\Telegram Bot\env\lib\site-packages\sqlalchemy\engine\default.py", line 732, in do_execute
    cursor.execute(statement, parameters)
psycopg2.errors.SyntaxError: syntax error at or near "'Інформація про фізичну особу'"
LINE 1: SELECT COUNT() from 'Інформація про фізичну особу' WHERE ПІБ...
                            ^


The above exception was the direct cause of the following exception:

Traceback (most recent call last):
  File "D:\Python Projects\Telegram Bot\main.py", line 946, in parameter_confirmation
    msg = parsers.get_data(tablegroups_path, user)
  File "D:\Python Projects\Telegram Bot\parsers.py", line 486, in get_data
    data, header = db_ops.get_data_from_db(parameter, value, user.table_group_name, path)
  File "D:\Python Projects\Telegram Bot\database_operations\db_ops.py", line 308, in get_data_from_db
    result = conn.execute(f"SELECT COUNT() from '{element}' WHERE {parameter} LIKE '{value}%%';").fetchall()
  File "D:\Python Projects\Telegram Bot\env\lib\site-packages\sqlalchemy\engine\base.py", line 1291, in execute
    return self._exec_driver_sql(
  File "D:\Python Projects\Telegram Bot\env\lib\site-packages\sqlalchemy\engine\base.py", line 1595, in _exec_driver_sql
    ret = self._execute_context(
  File "D:\Python Projects\Telegram Bot\env\lib\site-packages\sqlalchemy\engine\base.py", line 1862, in _execute_context
    self._handle_dbapi_exception(
  File "D:\Python Projects\Telegram Bot\env\lib\site-packages\sqlalchemy\engine\base.py", line 2043, in _handle_dbapi_exception
    util.raise_(
  File "D:\Python Projects\Telegram Bot\env\lib\site-packages\sqlalchemy\util\compat.py", line 207, in raise_
    raise exception
  File "D:\Python Projects\Telegram Bot\env\lib\site-packages\sqlalchemy\engine\base.py", line 1819, in _execute_context
    self.dialect.do_execute(
  File "D:\Python Projects\Telegram Bot\env\lib\site-packages\sqlalchemy\engine\default.py", line 732, in do_execute
    cursor.execute(statement, parameters)
sqlalchemy.exc.ProgrammingError: (psycopg2.errors.SyntaxError) syntax error at or near "'Інформація про фізичну особу'"
LINE 1: SELECT COUNT() from 'Інформація про фізичну особу' WHERE ПІБ...
                            ^

[SQL: SELECT COUNT() from 'Інформація про фізичну особу' WHERE ПІБ LIKE 'Іванюк Лілія Василівна%%';]
(Background on this error at: https://sqlalche.me/e/14/f405)
06/17/2022 06:05:38 PM: 'str' object cannot be interpreted as an integer
Traceback (most recent call last):
  File "D:\Python Projects\Telegram Bot\main.py", line 946, in parameter_confirmation
    msg = parsers.get_data(tablegroups_path, user)
  File "D:\Python Projects\Telegram Bot\parsers.py", line 486, in get_data
    data, header = db_ops.get_data_from_db(parameter, value, user.table_group_name, path)
  File "D:\Python Projects\Telegram Bot\database_operations\db_ops.py", line 318, in get_data_from_db
    table_names.pop(target_tablename)
TypeError: 'str' object cannot be interpreted as an integer
06/17/2022 06:06:48 PM: (psycopg2.errors.SyntaxError) syntax error at or near "'Інформація про фізичну особу" 
                WHERE "Інформація про фізичну особу".ПІБ LIKE Іванюк Лілія Василівна AND '"
LINE 2:                 FROM 'Інформація про фізичну особу" 
                             ^

[SQL: SELECT ПІБ 
                FROM 'Інформація про фізичну особу" 
                WHERE "Інформація про фізичну особу".ПІБ LIKE Іванюк Лілія Василівна AND 'Інформація про фізичну особу'.ПІБ IS NOT 
                NULL AND ПІБ IS NOT NULL;]
(Background on this error at: https://sqlalche.me/e/14/f405)
Traceback (most recent call last):
  File "D:\Python Projects\Telegram Bot\env\lib\site-packages\sqlalchemy\engine\base.py", line 1819, in _execute_context
    self.dialect.do_execute(
  File "D:\Python Projects\Telegram Bot\env\lib\site-packages\sqlalchemy\engine\default.py", line 732, in do_execute
    cursor.execute(statement, parameters)
psycopg2.errors.SyntaxError: syntax error at or near "'Інформація про фізичну особу" 
                WHERE "Інформація про фізичну особу".ПІБ LIKE Іванюк Лілія Василівна AND '"
LINE 2:                 FROM 'Інформація про фізичну особу" 
                             ^


The above exception was the direct cause of the following exception:

Traceback (most recent call last):
  File "D:\Python Projects\Telegram Bot\main.py", line 946, in parameter_confirmation
    msg = parsers.get_data(tablegroups_path, user)
  File "D:\Python Projects\Telegram Bot\parsers.py", line 486, in get_data
    data, header = db_ops.get_data_from_db(parameter, value, user.table_group_name, path)
  File "D:\Python Projects\Telegram Bot\database_operations\db_ops.py", line 382, in get_data_from_db
    new_val = conn.execute(new_sql).fetchall()[0][0]
  File "D:\Python Projects\Telegram Bot\env\lib\site-packages\sqlalchemy\engine\base.py", line 1291, in execute
    return self._exec_driver_sql(
  File "D:\Python Projects\Telegram Bot\env\lib\site-packages\sqlalchemy\engine\base.py", line 1595, in _exec_driver_sql
    ret = self._execute_context(
  File "D:\Python Projects\Telegram Bot\env\lib\site-packages\sqlalchemy\engine\base.py", line 1862, in _execute_context
    self._handle_dbapi_exception(
  File "D:\Python Projects\Telegram Bot\env\lib\site-packages\sqlalchemy\engine\base.py", line 2043, in _handle_dbapi_exception
    util.raise_(
  File "D:\Python Projects\Telegram Bot\env\lib\site-packages\sqlalchemy\util\compat.py", line 207, in raise_
    raise exception
  File "D:\Python Projects\Telegram Bot\env\lib\site-packages\sqlalchemy\engine\base.py", line 1819, in _execute_context
    self.dialect.do_execute(
  File "D:\Python Projects\Telegram Bot\env\lib\site-packages\sqlalchemy\engine\default.py", line 732, in do_execute
    cursor.execute(statement, parameters)
sqlalchemy.exc.ProgrammingError: (psycopg2.errors.SyntaxError) syntax error at or near "'Інформація про фізичну особу" 
                WHERE "Інформація про фізичну особу".ПІБ LIKE Іванюк Лілія Василівна AND '"
LINE 2:                 FROM 'Інформація про фізичну особу" 
                             ^

[SQL: SELECT ПІБ 
                FROM 'Інформація про фізичну особу" 
                WHERE "Інформація про фізичну особу".ПІБ LIKE Іванюк Лілія Василівна AND 'Інформація про фізичну особу'.ПІБ IS NOT 
                NULL AND ПІБ IS NOT NULL;]
(Background on this error at: https://sqlalche.me/e/14/f405)
06/17/2022 06:08:44 PM: (psycopg2.errors.SyntaxError) syntax error at or near "Лілія"
LINE 3: ...  WHERE "Інформація про виборців".ПІБ LIKE Іванюк Лілія Васи...
                                                             ^

[SQL: SELECT ПІБ 
                FROM "Інформація про виборців" 
                WHERE "Інформація про виборців".ПІБ LIKE Іванюк Лілія Василівна AND "Інформація про виборців".ПІБ IS NOT 
                NULL AND ПІБ IS NOT NULL;]
(Background on this error at: https://sqlalche.me/e/14/f405)
Traceback (most recent call last):
  File "D:\Python Projects\Telegram Bot\env\lib\site-packages\sqlalchemy\engine\base.py", line 1819, in _execute_context
    self.dialect.do_execute(
  File "D:\Python Projects\Telegram Bot\env\lib\site-packages\sqlalchemy\engine\default.py", line 732, in do_execute
    cursor.execute(statement, parameters)
psycopg2.errors.SyntaxError: syntax error at or near "Лілія"
LINE 3: ...  WHERE "Інформація про виборців".ПІБ LIKE Іванюк Лілія Васи...
                                                             ^


The above exception was the direct cause of the following exception:

Traceback (most recent call last):
  File "D:\Python Projects\Telegram Bot\main.py", line 946, in parameter_confirmation
    msg = parsers.get_data(tablegroups_path, user)
  File "D:\Python Projects\Telegram Bot\parsers.py", line 486, in get_data
    data, header = db_ops.get_data_from_db(parameter, value, user.table_group_name, path)
  File "D:\Python Projects\Telegram Bot\database_operations\db_ops.py", line 382, in get_data_from_db
    new_val = conn.execute(new_sql).fetchall()[0][0]
  File "D:\Python Projects\Telegram Bot\env\lib\site-packages\sqlalchemy\engine\base.py", line 1291, in execute
    return self._exec_driver_sql(
  File "D:\Python Projects\Telegram Bot\env\lib\site-packages\sqlalchemy\engine\base.py", line 1595, in _exec_driver_sql
    ret = self._execute_context(
  File "D:\Python Projects\Telegram Bot\env\lib\site-packages\sqlalchemy\engine\base.py", line 1862, in _execute_context
    self._handle_dbapi_exception(
  File "D:\Python Projects\Telegram Bot\env\lib\site-packages\sqlalchemy\engine\base.py", line 2043, in _handle_dbapi_exception
    util.raise_(
  File "D:\Python Projects\Telegram Bot\env\lib\site-packages\sqlalchemy\util\compat.py", line 207, in raise_
    raise exception
  File "D:\Python Projects\Telegram Bot\env\lib\site-packages\sqlalchemy\engine\base.py", line 1819, in _execute_context
    self.dialect.do_execute(
  File "D:\Python Projects\Telegram Bot\env\lib\site-packages\sqlalchemy\engine\default.py", line 732, in do_execute
    cursor.execute(statement, parameters)
sqlalchemy.exc.ProgrammingError: (psycopg2.errors.SyntaxError) syntax error at or near "Лілія"
LINE 3: ...  WHERE "Інформація про виборців".ПІБ LIKE Іванюк Лілія Васи...
                                                             ^

[SQL: SELECT ПІБ 
                FROM "Інформація про виборців" 
                WHERE "Інформація про виборців".ПІБ LIKE Іванюк Лілія Василівна AND "Інформація про виборців".ПІБ IS NOT 
                NULL AND ПІБ IS NOT NULL;]
(Background on this error at: https://sqlalche.me/e/14/f405)
06/17/2022 06:10:19 PM: (psycopg2.errors.SyntaxError) syntax error at or near "'Інформація про фізичну особу'"
LINE 1: ...LECT * FROM "Інформація про виборців"  LEFT OUTER 'Інформаці...
                                                             ^

[SQL: SELECT * FROM "Інформація про виборців"  LEFT OUTER 'Інформація про фізичну особу' ON 'Інформація про фізичну особу'.ПІБ = 'Інформація про виборців'.ПІБ LEFT OUTER 'Інформація про фізичну особу' ON 'Інформація про фізичну особу'.ДН = 'Інформація про виборців'.ДН LEFT OUTER 'Інформація про фізичну особу' ON 'Інформація про фізичну особу'.адреса = 'Інформація про виборців'.адреса WHERE "Інформація про виборців".ПІБ LIKE 'Івасюк Марія Василівна%%%%'; ]
(Background on this error at: https://sqlalche.me/e/14/f405)
Traceback (most recent call last):
  File "D:\Python Projects\Telegram Bot\env\lib\site-packages\sqlalchemy\engine\base.py", line 1819, in _execute_context
    self.dialect.do_execute(
  File "D:\Python Projects\Telegram Bot\env\lib\site-packages\sqlalchemy\engine\default.py", line 732, in do_execute
    cursor.execute(statement, parameters)
psycopg2.errors.SyntaxError: syntax error at or near "'Інформація про фізичну особу'"
LINE 1: ...LECT * FROM "Інформація про виборців"  LEFT OUTER 'Інформаці...
                                                             ^


The above exception was the direct cause of the following exception:

Traceback (most recent call last):
  File "D:\Python Projects\Telegram Bot\main.py", line 946, in parameter_confirmation
    msg = parsers.get_data(tablegroups_path, user)
  File "D:\Python Projects\Telegram Bot\parsers.py", line 486, in get_data
    data, header = db_ops.get_data_from_db(parameter, value, user.table_group_name, path)
  File "D:\Python Projects\Telegram Bot\database_operations\db_ops.py", line 418, in get_data_from_db
    engine.execute(sqlalchemy.text(sql))
  File "<string>", line 2, in execute
  File "D:\Python Projects\Telegram Bot\env\lib\site-packages\sqlalchemy\util\deprecations.py", line 401, in warned
    return fn(*args, **kwargs)
  File "D:\Python Projects\Telegram Bot\env\lib\site-packages\sqlalchemy\engine\base.py", line 3176, in execute
    return connection.execute(statement, *multiparams, **params)
  File "D:\Python Projects\Telegram Bot\env\lib\site-packages\sqlalchemy\engine\base.py", line 1306, in execute
    return meth(self, multiparams, params, _EMPTY_EXECUTION_OPTS)
  File "D:\Python Projects\Telegram Bot\env\lib\site-packages\sqlalchemy\sql\elements.py", line 325, in _execute_on_connection
    return connection._execute_clauseelement(
  File "D:\Python Projects\Telegram Bot\env\lib\site-packages\sqlalchemy\engine\base.py", line 1498, in _execute_clauseelement
    ret = self._execute_context(
  File "D:\Python Projects\Telegram Bot\env\lib\site-packages\sqlalchemy\engine\base.py", line 1862, in _execute_context
    self._handle_dbapi_exception(
  File "D:\Python Projects\Telegram Bot\env\lib\site-packages\sqlalchemy\engine\base.py", line 2043, in _handle_dbapi_exception
    util.raise_(
  File "D:\Python Projects\Telegram Bot\env\lib\site-packages\sqlalchemy\util\compat.py", line 207, in raise_
    raise exception
  File "D:\Python Projects\Telegram Bot\env\lib\site-packages\sqlalchemy\engine\base.py", line 1819, in _execute_context
    self.dialect.do_execute(
  File "D:\Python Projects\Telegram Bot\env\lib\site-packages\sqlalchemy\engine\default.py", line 732, in do_execute
    cursor.execute(statement, parameters)
sqlalchemy.exc.ProgrammingError: (psycopg2.errors.SyntaxError) syntax error at or near "'Інформація про фізичну особу'"
LINE 1: ...LECT * FROM "Інформація про виборців"  LEFT OUTER 'Інформаці...
                                                             ^

[SQL: SELECT * FROM "Інформація про виборців"  LEFT OUTER 'Інформація про фізичну особу' ON 'Інформація про фізичну особу'.ПІБ = 'Інформація про виборців'.ПІБ LEFT OUTER 'Інформація про фізичну особу' ON 'Інформація про фізичну особу'.ДН = 'Інформація про виборців'.ДН LEFT OUTER 'Інформація про фізичну особу' ON 'Інформація про фізичну особу'.адреса = 'Інформація про виборців'.адреса WHERE "Інформація про виборців".ПІБ LIKE 'Івасюк Марія Василівна%%%%'; ]
(Background on this error at: https://sqlalche.me/e/14/f405)
06/17/2022 06:12:18 PM: (psycopg2.errors.SyntaxError) syntax error at or near "Інформація"
LINE 1: ...нформація про фізичну особу'.ПІБ LEFT OUTER JOIN "Інформація...
                                                             ^

[SQL: SELECT * FROM "Інформація про фізичну особу"  LEFT OUTER JOIN "Інформація про виборців" ON "Інформація про виборців'.ПІБ = 'Інформація про фізичну особу'.ПІБ LEFT OUTER JOIN "Інформація про виборців" ON "Інформація про виборців'.ДН = 'Інформація про фізичну особу'.ДН LEFT OUTER JOIN "Інформація про виборців" ON "Інформація про виборців'.адреса = 'Інформація про фізичну особу'.адреса WHERE "Інформація про фізичну особу".ПІБ LIKE 'Івасюк Марія Василівна%%%%'; ]
(Background on this error at: https://sqlalche.me/e/14/f405)
Traceback (most recent call last):
  File "D:\Python Projects\Telegram Bot\env\lib\site-packages\sqlalchemy\engine\base.py", line 1819, in _execute_context
    self.dialect.do_execute(
  File "D:\Python Projects\Telegram Bot\env\lib\site-packages\sqlalchemy\engine\default.py", line 732, in do_execute
    cursor.execute(statement, parameters)
psycopg2.errors.SyntaxError: syntax error at or near "Інформація"
LINE 1: ...нформація про фізичну особу'.ПІБ LEFT OUTER JOIN "Інформація...
                                                             ^


The above exception was the direct cause of the following exception:

Traceback (most recent call last):
  File "D:\Python Projects\Telegram Bot\main.py", line 946, in parameter_confirmation
    msg = parsers.get_data(tablegroups_path, user)
  File "D:\Python Projects\Telegram Bot\parsers.py", line 486, in get_data
    data, header = db_ops.get_data_from_db(parameter, value, user.table_group_name, path)
  File "D:\Python Projects\Telegram Bot\database_operations\db_ops.py", line 418, in get_data_from_db
    engine.execute(sqlalchemy.text(sql))
  File "<string>", line 2, in execute
  File "D:\Python Projects\Telegram Bot\env\lib\site-packages\sqlalchemy\util\deprecations.py", line 401, in warned
    return fn(*args, **kwargs)
  File "D:\Python Projects\Telegram Bot\env\lib\site-packages\sqlalchemy\engine\base.py", line 3176, in execute
    return connection.execute(statement, *multiparams, **params)
  File "D:\Python Projects\Telegram Bot\env\lib\site-packages\sqlalchemy\engine\base.py", line 1306, in execute
    return meth(self, multiparams, params, _EMPTY_EXECUTION_OPTS)
  File "D:\Python Projects\Telegram Bot\env\lib\site-packages\sqlalchemy\sql\elements.py", line 325, in _execute_on_connection
    return connection._execute_clauseelement(
  File "D:\Python Projects\Telegram Bot\env\lib\site-packages\sqlalchemy\engine\base.py", line 1498, in _execute_clauseelement
    ret = self._execute_context(
  File "D:\Python Projects\Telegram Bot\env\lib\site-packages\sqlalchemy\engine\base.py", line 1862, in _execute_context
    self._handle_dbapi_exception(
  File "D:\Python Projects\Telegram Bot\env\lib\site-packages\sqlalchemy\engine\base.py", line 2043, in _handle_dbapi_exception
    util.raise_(
  File "D:\Python Projects\Telegram Bot\env\lib\site-packages\sqlalchemy\util\compat.py", line 207, in raise_
    raise exception
  File "D:\Python Projects\Telegram Bot\env\lib\site-packages\sqlalchemy\engine\base.py", line 1819, in _execute_context
    self.dialect.do_execute(
  File "D:\Python Projects\Telegram Bot\env\lib\site-packages\sqlalchemy\engine\default.py", line 732, in do_execute
    cursor.execute(statement, parameters)
sqlalchemy.exc.ProgrammingError: (psycopg2.errors.SyntaxError) syntax error at or near "Інформація"
LINE 1: ...нформація про фізичну особу'.ПІБ LEFT OUTER JOIN "Інформація...
                                                             ^

[SQL: SELECT * FROM "Інформація про фізичну особу"  LEFT OUTER JOIN "Інформація про виборців" ON "Інформація про виборців'.ПІБ = 'Інформація про фізичну особу'.ПІБ LEFT OUTER JOIN "Інформація про виборців" ON "Інформація про виборців'.ДН = 'Інформація про фізичну особу'.ДН LEFT OUTER JOIN "Інформація про виборців" ON "Інформація про виборців'.адреса = 'Інформація про фізичну особу'.адреса WHERE "Інформація про фізичну особу".ПІБ LIKE 'Івасюк Марія Василівна%%%%'; ]
(Background on this error at: https://sqlalche.me/e/14/f405)
06/17/2022 06:16:23 PM: (psycopg2.errors.DuplicateAlias) table name "Інформація про виборців" specified more than once

[SQL: SELECT * FROM "Інформація про фізичну особу"  LEFT OUTER JOIN "Інформація про виборців" ON "Інформація про виборців".ПІБ = "Інформація про фізичну особу".ПІБ LEFT OUTER JOIN "Інформація про виборців" ON "Інформація про виборців".ДН = "Інформація про фізичну особу".ДН LEFT OUTER JOIN "Інформація про виборців" ON "Інформація про виборців".адреса = "Інформація про фізичну особу".адреса WHERE "Інформація про фізичну особу".ПІБ LIKE 'Копей Тетяна Володимирівна%%%%'; ]
(Background on this error at: https://sqlalche.me/e/14/f405)
Traceback (most recent call last):
  File "D:\Python Projects\Telegram Bot\env\lib\site-packages\sqlalchemy\engine\base.py", line 1819, in _execute_context
    self.dialect.do_execute(
  File "D:\Python Projects\Telegram Bot\env\lib\site-packages\sqlalchemy\engine\default.py", line 732, in do_execute
    cursor.execute(statement, parameters)
psycopg2.errors.DuplicateAlias: table name "Інформація про виборців" specified more than once


The above exception was the direct cause of the following exception:

Traceback (most recent call last):
  File "D:\Python Projects\Telegram Bot\main.py", line 946, in parameter_confirmation
    msg = parsers.get_data(tablegroups_path, user)
  File "D:\Python Projects\Telegram Bot\parsers.py", line 486, in get_data
    data, header = db_ops.get_data_from_db(parameter, value, user.table_group_name, path)
  File "D:\Python Projects\Telegram Bot\database_operations\db_ops.py", line 418, in get_data_from_db
    engine.execute(sqlalchemy.text(sql))
  File "<string>", line 2, in execute
  File "D:\Python Projects\Telegram Bot\env\lib\site-packages\sqlalchemy\util\deprecations.py", line 401, in warned
    return fn(*args, **kwargs)
  File "D:\Python Projects\Telegram Bot\env\lib\site-packages\sqlalchemy\engine\base.py", line 3176, in execute
    return connection.execute(statement, *multiparams, **params)
  File "D:\Python Projects\Telegram Bot\env\lib\site-packages\sqlalchemy\engine\base.py", line 1306, in execute
    return meth(self, multiparams, params, _EMPTY_EXECUTION_OPTS)
  File "D:\Python Projects\Telegram Bot\env\lib\site-packages\sqlalchemy\sql\elements.py", line 325, in _execute_on_connection
    return connection._execute_clauseelement(
  File "D:\Python Projects\Telegram Bot\env\lib\site-packages\sqlalchemy\engine\base.py", line 1498, in _execute_clauseelement
    ret = self._execute_context(
  File "D:\Python Projects\Telegram Bot\env\lib\site-packages\sqlalchemy\engine\base.py", line 1862, in _execute_context
    self._handle_dbapi_exception(
  File "D:\Python Projects\Telegram Bot\env\lib\site-packages\sqlalchemy\engine\base.py", line 2043, in _handle_dbapi_exception
    util.raise_(
  File "D:\Python Projects\Telegram Bot\env\lib\site-packages\sqlalchemy\util\compat.py", line 207, in raise_
    raise exception
  File "D:\Python Projects\Telegram Bot\env\lib\site-packages\sqlalchemy\engine\base.py", line 1819, in _execute_context
    self.dialect.do_execute(
  File "D:\Python Projects\Telegram Bot\env\lib\site-packages\sqlalchemy\engine\default.py", line 732, in do_execute
    cursor.execute(statement, parameters)
sqlalchemy.exc.ProgrammingError: (psycopg2.errors.DuplicateAlias) table name "Інформація про виборців" specified more than once

[SQL: SELECT * FROM "Інформація про фізичну особу"  LEFT OUTER JOIN "Інформація про виборців" ON "Інформація про виборців".ПІБ = "Інформація про фізичну особу".ПІБ LEFT OUTER JOIN "Інформація про виборців" ON "Інформація про виборців".ДН = "Інформація про фізичну особу".ДН LEFT OUTER JOIN "Інформація про виборців" ON "Інформація про виборців".адреса = "Інформація про фізичну особу".адреса WHERE "Інформація про фізичну особу".ПІБ LIKE 'Копей Тетяна Володимирівна%%%%'; ]
(Background on this error at: https://sqlalche.me/e/14/f405)
